Workbook

Sheet Read Me
A1: Read Me
A2: What this is: a cleaned, analysis-ready version of the CMS Transparency in Coverage Public Use File (PUF) for plan year 2026, reorganized around how fixable each claim denial is.
A3: Source: CMS Exchange Public Use Files, https://download.cms.gov/marketplace-puf/2026/transparency-in-coverage-puf.zip (downloaded 2026-09-28). Covers HealthCare.gov states (30) only; data self-reported by insurers.
A5: Tabs
A6: Fixability — start here. Pick a market in the yellow cell; shows headline rates, then all 10 CMS denial reasons ranked by fixability tier.
A7: By State / By Plan Type / By Metal Level — the same tiers and reason mix broken out, with heat-map shading. Follow the market picked on Fixability.
A8: Issuers — one row per insurer per market: claims, denial rates (total / OON / in-network), appeals and overturn rates, and fixability tiers rolled up from its plans.
A9: Plans — one row per plan: plan-level claims, denials by reason (columns ordered and colored by fixability tier), tier subtotals.
A11: How the data was cleaned
A12: • Three source tabs (Individual Medical QHP, Individual Dental SADP, SHOP) stacked into one table with a Market column.
A13: • Issuer-level fields (repeated on every plan row in the source) moved to the Issuers tab, one row each.
A14: • CMS placeholder codes converted to blank cells so numbers sum correctly: * not available, ** suppressed for small numbers, *** not required for plan type, N/A new to the Exchange. The Data Notes column on Issuers records which codes were present.
... A22: • CMS publishes no dollar amounts. See the Ferry project doc "CMS Claims Denial Data" for cost estimates.

Sheet Fixability
A1: Claim Denials by Fixability — CMS Transparency in Coverage, Plan Year 2026
A3: Market (choose): | C3: Individual Medical | D3: ← every number on this tab and the "By ..." tabs follows this cell
A5: Claims received | C5: =SUMIFS(Issuers!$I$2:$I$375,Issuers!$A$2:$A$375,$C$3) -> 495646850 | D5: Issuer-level totals. Suppressed cells excluded, so figures are minimums.
A6: Claims denied | C6: =SUMIFS(Issuers!$L$2:$L$375,Issuers!$A$2:$A$375,$C$3) -> 100974402
A7: Overall denial rate | C7: =IFERROR(C6/C5,"") -> 0.20372247
A8: Out-of-network denial rate | C8: =IFERROR(SUMIFS(Issuers!$J$2:$J$375,Issuers!$A$2:$A$375,$C$3)/SUMIFS(Issuers!$G$2:$G$375,Issuers!$A$2:$A$375,$C$3),"") -> 0.37100776
A9: In-network denial rate | C9: =IFERROR(SUMIFS(Issuers!$K$2:$K$375,Issuers!$A$2:$A$375,$C$3)/SUMIFS(Issuers!$H$2:$H$375,Issuers!$A$2:$A$375,$C$3),"") -> 0.1872638
A10: Internal appeals filed | C10: =SUMIFS(Issuers!$R$2:$R$375,Issuers!$A$2:$A$375,$C$3) -> 263021
A11: Internal appeal overturn rate | C11: =IFERROR(SUMIFS(Issuers!$S$2:$S$375,Issuers!$A$2:$A$375,$C$3)/C10,"") -> 0.32623631
A12: Appeals filed per 1,000 denials | C12: =IFERROR((C10+SUMIFS(Issuers!$U$2:$U$375,Issuers!$A$2:$A$375,$C$3))/C6*1000,"") -> 2.663071
A14: Denial reasons ranked by how fixable they are
A15: Rank | B15: Fixability Tier | C15: Denial Reason | D15: What It Usually Means | E15: Typical Fix Path | F15: Who Can Fix It | G15: Denials (plan-level) | H15: Share of Denials | I15: Cumulative Share | J15: Patient Cost to Fight
A16: 1 | B16: High | C16: Administrative | D16: Paperwork or data problem: missing/invalid codes, NPI, dates, duplicate or incomplete claim. | E16: Correct and resubmit; usually no appeal needed. | F16: Patient or Ferry with provider info | G16: =SUMIFS(Plans!$Q$2:$Q$4957,Plans!$A$2:$A$4957,$C$3) -> 19612209 | H16: =IFERROR(G16/$G$26,"") -> 0.22497948 | I16: =IFERROR(SUM($G$16:G16)/$G$26,"") -> 0.22497948 | J16: Resubmission: free.
A17: 2 | B17: Medium-High | C17: Not medically necessary (medical) | D17: Insurer says care was not needed. | E17: Internal appeal with clinical notes and a letter of medical necessity; external review if denied again. | F17: Provider documentation + patient appeal | G17: =SUMIFS(Plans!$R$2:$R$4957,Plans!$A$2:$A$4957,$C$3) -> 3594527 | H17: =IFERROR(G17/$G$26,"") -> 0.041234254 | I17: =IFERROR(SUM($G$16:G17)/$G$26,"") -> 0.26621373 | J17: Internal appeal: free. External review: free (federal) or ≤ $25 (state).
A18: 3 | B18: Medium-High | C18: Not medically necessary (behavioral health) | D18: Same, for mental health / substance use care. Parity rules add leverage. | E18: Appeal with treatment notes; cite mental health parity rules. | F18: Provider documentation + patient appeal | G18: =SUMIFS(Plans!$S$2:$S$4957,Plans!$A$2:$A$4957,$C$3) -> 374394 | H18: =IFERROR(G18/$G$26,"") -> 0.004294823 | I18: =IFERROR(SUM($G$16:G18)/$G$26,"") -> 0.27050856 | J18: Internal appeal: free. External review: free (federal) or ≤ $25 (state).
A19: 4 | B19: Medium | C19: Referral required | D19: Plan needed a PCP referral or prior authorization. | E19: Request a retroactive referral/authorization, then resubmit or appeal. | F19: Patient + PCP | G19: =SUMIFS(Plans!$T$2:$T$4957,Plans!$A$2:$A$4957,$C$3) -> 7304650 | H19: =IFERROR(G19/$G$26,"") -> 0.083794556 | I19: =IFERROR(SUM($G$16:G19)/$G$26,"") -> 0.35430311 | J19: Resubmission: free.
A20: 5 | B20: Medium | C20: Member not covered | D20: Eligibility problem: wrong member ID, lapsed coverage, coordination of benefits. | E20: Verify eligibility, fix member info or COB, resubmit. | F20: Patient | G20: =SUMIFS(Plans!$U$2:$U$4957,Plans!$A$2:$A$4957,$C$3) -> 5729108 | H20: =IFERROR(G20/$G$26,"") -> 0.065720885 | I20: =IFERROR(SUM($G$16:G20)/$G$26,"") -> 0.420024 | J20: Internal appeal: free. External review: free (federal) or ≤ $25 (state).
A21: 6 | B21: Medium | C21: Out-of-network | D21: Provider is not in the plan network. | E21: PPO/POS: appeal or reprocess at OON benefit. HMO/EPO: usually no OON benefit (low fixability) unless emergency, network gap or No Surprises Act applies. | F21: Patient; depends on plan type | G21: =SUMIFS(Plans!$V$2:$V$4957,Plans!$A$2:$A$4957,$C$3) -> 8567575 | H21: =IFERROR(G21/$G$26,"") -> 0.098282073 | I21: =IFERROR(SUM($G$16:G21)/$G$26,"") -> 0.51830607 | J21: Internal appeal: free. External review: free (federal) or ≤ $25 (state).
A22: 7 | B22: Low | C22: Benefit limit reached | D22: Visit or dollar cap for the year was used up. | E22: Rarely fixable; medical-necessity exception request sometimes works. | F22: Patient + provider | G22: =SUMIFS(Plans!$W$2:$W$4957,Plans!$A$2:$A$4957,$C$3) -> 3646507 | H22: =IFERROR(G22/$G$26,"") -> 0.041830538 | I22: =IFERROR(SUM($G$16:G22)/$G$26,"") -> 0.56013661 | J22: Internal appeal: free. External review: free (federal) or ≤ $25 (state).
A23: 8 | B23: Low | C23: Service excluded | D23: The plan does not cover this service at all. | E23: Usually final unless the service was miscoded; check for a coding fix. | F23: Provider coding review | G23: =SUMIFS(Plans!$X$2:$X$4957,Plans!$A$2:$A$4957,$C$3) -> 10129111 | H23: =IFERROR(G23/$G$26,"") -> 0.11619508 | I23: =IFERROR(SUM($G$16:G23)/$G$26,"") -> 0.67633168 | J23: Internal appeal: free. External review: free (federal) or ≤ $25 (state).
A24: 9 | B24: Low | C24: Experimental / cosmetic | D24: Treatment considered investigational or cosmetic. | E24: Appeal with clinical evidence; external review can overturn but odds are low. | F24: Provider + patient | G24: =SUMIFS(Plans!$Y$2:$Y$4957,Plans!$A$2:$A$4957,$C$3) -> 101612 | H24: =IFERROR(G24/$G$26,"") -> 0.0011656318 | I24: =IFERROR(SUM($G$16:G24)/$G$26,"") -> 0.67749732 | J24: Internal appeal: free. External review: free (federal) or ≤ $25 (state).
A25: 10 | B25: Unknown | C25: Other / unspecified | D25: Insurer did not classify the reason. | E25: Read the reason code (CARC/RARC) on the EOB, then route to the right fix. | F25: Needs EOB review | G25: =SUMIFS(Plans!$Z$2:$Z$4957,Plans!$A$2:$A$4957,$C$3) -> 28113631 | H25: =IFERROR(G25/$G$26,"") -> 0.32250268 | I25: =IFERROR(SUM($G$16:G25)/$G$26,"") -> 1 | J25: Depends on true reason.
C26: Total | G26: =SUM(G16:G25) -> 87173324 | H26: =IFERROR(G26/G26,"") -> 1
A28: Summary by fixability tier
A29: Tier | B29: Fixability | C29: Denials | D29: Share | E29: Definition
A30: 1 | B30: High | C30: =SUMIFS($G$16:$G$25,$B$16:$B$25,B30) -> 19612209 | D30: =IFERROR(C30/$G$26,"") -> 0.22497948 | E30: Fixable by correcting and resubmitting; no clinical argument needed.
A31: 2 | B31: Medium-High | C31: =SUMIFS($G$16:$G$25,$B$16:$B$25,B31) -> 3968921 | D31: =IFERROR(C31/$G$26,"") -> 0.045529077 | E31: Winnable on appeal with documentation; external review often overturns.
A32: 3 | B32: Medium | C32: =SUMIFS($G$16:$G$25,$B$16:$B$25,B32) -> 21601333 | D32: =IFERROR(C32/$G$26,"") -> 0.24779751 | E32: Fixable if the underlying fact is wrong (eligibility, referral, network status, plan type).
A33: 4 | B33: Low | C33: =SUMIFS($G$16:$G$25,$B$16:$B$25,B33) -> 13877230 | D33: =IFERROR(C33/$G$26,"") -> 0.15919125 | E33: Usually a true coverage limit; succeeds only with a coding error or exception.
A34: 5 | B34: Unknown | C34: =SUMIFS($G$16:$G$25,$B$16:$B$25,B34) -> 28113631 | D34: =IFERROR(C34/$G$26,"") -> 0.32250268 | E34: Reason not classified by insurer; read the EOB reason code first.
B35: Total | C35: =SUM(C30:C34) -> 87173324
A37: Fixability tiers are Ferry judgments based on how each denial type is normally resolved, not CMS data. Out-of-network is rated Medium overall but is Low for HMO/EPO plans (no OON benefit) and Medium for PPO/POS.

Sheet By State
A1: Denial reasons by State — market: | D1: =Fixability!$C$3 -> Individual Medical
A2: Counts by fixability tier, then each reason as a share of that row's classified denials. Change the market on the Fixability tab.
A4: State | B4: Denials With Reason | C4: Tier 1 High | D4: Tier 2 Medium-High | E4: Tier 3 Medium | F4: Tier 4 Low | G4: Tier 5 Unknown | H4: % Fixable (High + Med-High) | I4: % Administrative | J4: % Not medically necessary (medical) | K4: % Not medically necessary (behavioral health) | L4: % Referral required | M4: % Member not covered | N4: % Out-of-network | O4: % Benefit limit reached | P4: % Service excluded | Q4: % Experimental / cosmetic | R4: % Other / unspecified
A5: TX | B5: =SUM(C5:G5) -> 25649845 | C5: =SUMIFS(Plans!$AA$2:$AA$4957,Plans!$A$2:$A$4957,Fixability!$C$3,Plans!$B$2:$B$4957,$A5) -> 3089691 | D5: =SUMIFS(Plans!$AB$2:$AB$4957,Plans!$A$2:$A$4957,Fixability!$C$3,Plans!$B$2:$B$4957,$A5) -> 1082079 | E5: =SUMIFS(Plans!$AC$2:$AC$4957,Plans!$A$2:$A$4957,Fixability!$C$3,Plans!$B$2:$B$4957,$A5) -> 6927343 | F5: =SUMIFS(Plans!$AD$2:$AD$4957,Plans!$A$2:$A$4957,Fixability!$C$3,Plans!$B$2:$B$4957,$A5) -> 4631476 | G5: =SUMIFS(Plans!$AE$2:$AE$4957,Plans!$A$2:$A$4957,Fixability!$C$3,Plans!$B$2:$B$4957,$A5) -> 9919256 | H5: =IFERROR((C5+D5)/B5,"") -> 0.16264309 | I5: =IFERROR(SUMIFS(Plans!$Q$2:$Q$4957,Plans!$A$2:$A$4957,Fixability!$C$3,Plans!$B$2:$B$4957,$A5)/$B5,"") -> 0.12045652 | J5: =IFERROR(SUMIFS(Plans!$R$2:$R$4957,Plans!$A$2:$A$4957,Fixability!$C$3,Plans!$B$2:$B$4957,$A5)/$B5,"") -> 0.038869046 | K5: =IFERROR(SUMIFS(Plans!$S$2:$S$4957,Plans!$A$2:$A$4957,Fixability!$C$3,Plans!$B$2:$B$4957,$A5)/$B5,"") -> 0.0033175249 | L5: =IFERROR(SUMIFS(Plans!$T$2:$T$4957,Plans!$A$2:$A$4957,Fixability!$C$3,Plans!$B$2:$B$4957,$A5)/$B5,"") -> 0.096018124 | M5: =IFERROR(SUMIFS(Plans!$U$2:$U$4957,Plans!$A$2:$A$4957,Fixability!$C$3,Plans!$B$2:$B$4957,$A5)/$B5,"") -> 0.0598758 | N5: =IFERROR(SUMIFS(Plans!$V$2:$V$4957,Plans!$A$2:$A$4957,Fixability!$C$3,Plans!$B$2:$B$4957,$A5)/$B5,"") -> 0.11417956 | O5: =IFERROR(SUMIFS(Plans!$W$2:$W$4957,Plans!$A$2:$A$4957,Fixability!$C$3,Plans!$B$2:$B$4957,$A5)/$B5,"") -> 0.0185244 | P5: =IFERROR(SUMIFS(Plans!$X$2:$X$4957,Plans!$A$2:$A$4957,Fixability!$C$3,Plans!$B$2:$B$4957,$A5)/$B5,"") -> 0.16137255 | Q5: =IFERROR(SUMIFS(Plans!$Y$2:$Y$4957,Plans!$A$2:$A$4957,Fixability!$C$3,Plans!$B$2:$B$4957,$A5)/$B5,"") -> 0.00066850307 | R5: =IFERROR(SUMIFS(Plans!$Z$2:$Z$4957,Plans!$A$2:$A$4957,Fixability!$C$3,Plans!$B$2:$B$4957,$A5)/$B5,"") -> 0.38671797
A6: FL | B6: =SUM(C6:G6) -> 16682663 | C6: =SUMIFS(Plans!$AA$2:$AA$4957,Plans!$A$2:$A$4957,Fixability!$C$3,Plans!$B$2:$B$4957,$A6) -> 7085644 | D6: =SUMIFS(Plans!$AB$2:$AB$4957,Plans!$A$2:$A$4957,Fixability!$C$3,Plans!$B$2:$B$4957,$A6) -> 351017 | E6: =SUMIFS(Plans!$AC$2:$AC$4957,Plans!$A$2:$A$4957,Fixability!$C$3,Plans!$B$2:$B$4957,$A6) -> 1528571 | F6: =SUMIFS(Plans!$AD$2:$AD$4957,Plans!$A$2:$A$4957,Fixability!$C$3,Plans!$B$2:$B$4957,$A6) -> 587809 | G6: =SUMIFS(Plans!$AE$2:$AE$4957,Plans!$A$2:$A$4957,Fixability!$C$3,Plans!$B$2:$B$4957,$A6) -> 7129622 | H6: =IFERROR((C6+D6)/B6,"") -> 0.44577182 | I6: =IFERROR(SUMIFS(Plans!$Q$2:$Q$4957,Plans!$A$2:$A$4957,Fixability!$C$3,Plans!$B$2:$B$4957,$A6)/$B6,"") -> 0.42473099 | J6: =IFERROR(SUMIFS(Plans!$R$2:$R$4957,Plans!$A$2:$A$4957,Fixability!$C$3,Plans!$B$2:$B$4957,$A6)/$B6,"") -> 0.01756644 | K6: =IFERROR(SUMIFS(Plans!$S$2:$S$4957,Plans!$A$2:$A$4957,Fixability!$C$3,Plans!$B$2:$B$4957,$A6)/$B6,"") -> 0.0034743854 | L6: =IFERROR(SUMIFS(Plans!$T$2:$T$4957,Plans!$A$2:$A$4957,Fixability!$C$3,Plans!$B$2:$B$4957,$A6)/$B6,"") -> 0.024610819 | M6: =IFERROR(SUMIFS(Plans!$U$2:$U$4957,Plans!$A$2:$A$4957,Fixability!$C$3,Plans!$B$2:$B$4957,$A6)/$B6,"") -> 0.010446174 | N6: =IFERROR(SUMIFS(Plans!$V$2:$V$4957,Plans!$A$2:$A$4957,Fixability!$C$3,Plans!$B$2:$B$4957,$A6)/$B6,"") -> 0.056569326 | O6: =IFERROR(SUMIFS(Plans!$W$2:$W$4957,Plans!$A$2:$A$4957,Fixability!$C$3,Plans!$B$2:$B$4957,$A6)/$B6,"") -> 0.01529492 | P6: =IFERROR(SUMIFS(Plans!$X$2:$X$4957,Plans!$A$2:$A$4957,Fixability!$C$3,Plans!$B$2:$B$4957,$A6)/$B6,"") -> 0.018463419 | Q6: =IFERROR(SUMIFS(Plans!$Y$2:$Y$4957,Plans!$A$2:$A$4957,Fixability!$C$3,Plans!$B$2:$B$4957,$A6)/$B6,"") -> 0.001476383 | R6: =IFERROR(SUMIFS(Plans!$Z$2:$Z$4957,Plans!$A$2:$A$4957,Fixability!$C$3,Plans!$B$2:$B$4957,$A6)/$B6,"") -> 0.42736714
A7: AL | B7: =SUM(C7:G7) -> 5200796 | C7: =SUMIFS(Plans!$AA$2:$AA$4957,Plans!$A$2:$A$4957,Fixability!$C$3,Plans!$B$2:$B$4957,$A7) -> 1030205 | D7: =SUMIFS(Plans!$AB$2:$AB$4957,Plans!$A$2:$A$4957,Fixability!$C$3,Plans!$B$2:$B$4957,$A7) -> 90401 | E7: =SUMIFS(Plans!$AC$2:$AC$4957,Plans!$A$2:$A$4957,Fixability!$C$3,Plans!$B$2:$B$4957,$A7) -> 2233266 | F7: =SUMIFS(Plans!$AD$2:$AD$4957,Plans!$A$2:$A$4957,Fixability!$C$3,Plans!$B$2:$B$4957,$A7) -> 1337080 | G7: =SUMIFS(Plans!$AE$2:$AE$4957,Plans!$A$2:$A$4957,Fixability!$C$3,Plans!$B$2:$B$4957,$A7) -> 509844 | H7: =IFERROR((C7+D7)/B7,"") -> 0.21546817 | I7: =IFERROR(SUMIFS(Plans!$Q$2:$Q$4957,Plans!$A$2:$A$4957,Fixability!$C$3,Plans!$B$2:$B$4957,$A7)/$B7,"") -> 0.19808602 | J7: =IFERROR(SUMIFS(Plans!$R$2:$R$4957,Plans!$A$2:$A$4957,Fixability!$C$3,Plans!$B$2:$B$4957,$A7)/$B7,"") -> 0.016904528 | K7: =IFERROR(SUMIFS(Plans!$S$2:$S$4957,Plans!$A$2:$A$4957,Fixability!$C$3,Plans!$B$2:$B$4957,$A7)/$B7,"") -> 0.0004776192 | L7: =IFERROR(SUMIFS(Plans!$T$2:$T$4957,Plans!$A$2:$A$4957,Fixability!$C$3,Plans!$B$2:$B$4957,$A7)/$B7,"") -> 0.1041679 | M7: =IFERROR(SUMIFS(Plans!$U$2:$U$4957,Plans!$A$2:$A$4957,Fixability!$C$3,Plans!$B$2:$B$4957,$A7)/$B7,"") -> 0.12412062 | N7: =IFERROR(SUMIFS(Plans!$V$2:$V$4957,Plans!$A$2:$A$4957,Fixability!$C$3,Plans!$B$2:$B$4957,$A7)/$B7,"") -> 0.20111998 | O7: =IFERROR(SUMIFS(Plans!$W$2:$W$4957,Plans!$A$2:$A$4957,Fixability!$C$3,Plans!$B$2:$B$4957,$A7)/$B7,"") -> 0.079233833 | P7: =IFERROR(SUMIFS(Plans!$X$2:$X$4957,Plans!$A$2:$A$4957,Fixability!$C$3,Plans!$B$2:$B$4957,$A7)/$B7,"") -> 0.17782739 | Q7: =IFERROR(SUMIFS(Plans!$Y$2:$Y$4957,Plans!$A$2:$A$4957,Fixability!$C$3,Plans!$B$2:$B$4957,$A7)/$B7,"") -> 3.0187687e-05 | R7: =IFERROR(SUMIFS(Plans!$Z$2:$Z$4957,Plans!$A$2:$A$4957,Fixability!$C$3,Plans!$B$2:$B$4957,$A7)/$B7,"") -> 0.098031917
A8: NC | B8: =SUM(C8:G8) -> 4780663 | C8: =SUMIFS(Plans!$AA$2:$AA$4957,Plans!$A$2:$A$4957,Fixability!$C$3,Plans!$B$2:$B$4957,$A8) -> 988831 | D8: =SUMIFS(Plans!$AB$2:$AB$4957,Plans!$A$2:$A$4957,Fixability!$C$3,Plans!$B$2:$B$4957,$A8) -> 183837 | E8: =SUMIFS(Plans!$AC$2:$AC$4957,Plans!$A$2:$A$4957,Fixability!$C$3,Plans!$B$2:$B$4957,$A8) -> 1357446 | F8: =SUMIFS(Plans!$AD$2:$AD$4957,Plans!$A$2:$A$4957,Fixability!$C$3,Plans!$B$2:$B$4957,$A8) -> 1001028 | G8: =SUMIFS(Plans!$AE$2:$AE$4957,Plans!$A$2:$A$4957,Fixability!$C$3,Plans!$B$2:$B$4957,$A8) -> 1249521 | H8: =IFERROR((C8+D8)/B8,"") -> 0.24529401 | I8: =IFERROR(SUMIFS(Plans!$Q$2:$Q$4957,Plans!$A$2:$A$4957,Fixability!$C$3,Plans!$B$2:$B$4957,$A8)/$B8,"") -> 0.20683972 | J8: =IFERROR(SUMIFS(Plans!$R$2:$R$4957,Plans!$A$2:$A$4957,Fixability!$C$3,Plans!$B$2:$B$4957,$A8)/$B8,"") -> 0.035802775 | K8: =IFERROR(SUMIFS(Plans!$S$2:$S$4957,Plans!$A$2:$A$4957,Fixability!$C$3,Plans!$B$2:$B$4957,$A8)/$B8,"") -> 0.0026515151 | L8: =IFERROR(SUMIFS(Plans!$T$2:$T$4957,Plans!$A$2:$A$4957,Fixability!$C$3,Plans!$B$2:$B$4957,$A8)/$B8,"") -> 0.087065539 | M8: =IFERROR(SUMIFS(Plans!$U$2:$U$4957,Plans!$A$2:$A$4957,Fixability!$C$3,Plans!$B$2:$B$4957,$A8)/$B8,"") -> 0.122697 | N8: =IFERROR(SUMIFS(Plans!$V$2:$V$4957,Plans!$A$2:$A$4957,Fixability!$C$3,Plans!$B$2:$B$4957,$A8)/$B8,"") -> 0.074182598 | O8: =IFERROR(SUMIFS(Plans!$W$2:$W$4957,Plans!$A$2:$A$4957,Fixability!$C$3,Plans!$B$2:$B$4957,$A8)/$B8,"") -> 0.057149814 | P8: =IFERROR(SUMIFS(Plans!$X$2:$X$4957,Plans!$A$2:$A$4957,Fixability!$C$3,Plans!$B$2:$B$4957,$A8)/$B8,"") -> 0.15165198 | Q8: =IFERROR(SUMIFS(Plans!$Y$2:$Y$4957,Plans!$A$2:$A$4957,Fixability!$C$3,Plans!$B$2:$B$4957,$A8)/$B8,"") -> 0.00058924881 | R8: =IFERROR(SUMIFS(Plans!$Z$2:$Z$4957,Plans!$A$2:$A$4957,Fixability!$C$3,Plans!$B$2:$B$4957,$A8)/$B8,"") -> 0.26136981
A9: SC | B9: =SUM(C9:G9) -> 4052114 | C9: =SUMIFS(Plans!$AA$2:$AA$4957,Plans!$A$2:$A$4957,Fixability!$C$3,Plans!$B$2:$B$4957,$A9) -> 598016 | D9: =SUMIFS(Plans!$AB$2:$AB$4957,Plans!$A$2:$A$4957,Fixability!$C$3,Plans!$B$2:$B$4957,$A9) -> 469831 | E9: =SUMIFS(Plans!$AC$2:$AC$4957,Plans!$A$2:$A$4957,Fixability!$C$3,Plans!$B$2:$B$4957,$A9) -> 1165348 | F9: =SUMIFS(Plans!$AD$2:$AD$4957,Plans!$A$2:$A$4957,Fixability!$C$3,Plans!$B$2:$B$4957,$A9) -> 826694 | G9: =SUMIFS(Plans!$AE$2:$AE$4957,Plans!$A$2:$A$4957,Fixability!$C$3,Plans!$B$2:$B$4957,$A9) -> 992225 | H9: =IFERROR((C9+D9)/B9,"") -> 0.26352837 | I9: =IFERROR(SUMIFS(Plans!$Q$2:$Q$4957,Plans!$A$2:$A$4957,Fixability!$C$3,Plans!$B$2:$B$4957,$A9)/$B9,"") -> 0.14758124 | J9: =IFERROR(SUMIFS(Plans!$R$2:$R$4957,Plans!$A$2:$A$4957,Fixability!$C$3,Plans!$B$2:$B$4957,$A9)/$B9,"") -> 0.10707374 | K9: =IFERROR(SUMIFS(Plans!$S$2:$S$4957,Plans!$A$2:$A$4957,Fixability!$C$3,Plans!$B$2:$B$4957,$A9)/$B9,"") -> 0.008873393 | L9: =IFERROR(SUMIFS(Plans!$T$2:$T$4957,Plans!$A$2:$A$4957,Fixability!$C$3,Plans!$B$2:$B$4957,$A9)/$B9,"") -> 0.11352247 | M9: =IFERROR(SUMIFS(Plans!$U$2:$U$4957,Plans!$A$2:$A$4957,Fixability!$C$3,Plans!$B$2:$B$4957,$A9)/$B9,"") -> 0.1005759 | N9: =IFERROR(SUMIFS(Plans!$V$2:$V$4957,Plans!$A$2:$A$4957,Fixability!$C$3,Plans!$B$2:$B$4957,$A9)/$B9,"") -> 0.073491763 | O9: =IFERROR(SUMIFS(Plans!$W$2:$W$4957,Plans!$A$2:$A$4957,Fixability!$C$3,Plans!$B$2:$B$4957,$A9)/$B9,"") -> 0.10839453 | P9: =IFERROR(SUMIFS(Plans!$X$2:$X$4957,Plans!$A$2:$A$4957,Fixability!$C$3,Plans!$B$2:$B$4957,$A9)/$B9,"") -> 0.093556351 | Q9: =IFERROR(SUMIFS(Plans!$Y$2:$Y$4957,Plans!$A$2:$A$4957,Fixability!$C$3,Plans!$B$2:$B$4957,$A9)/$B9,"") -> 0.0020646013 | R9: =IFERROR(SUMIFS(Plans!$Z$2:$Z$4957,Plans!$A$2:$A$4957,Fixability!$C$3,Plans!$B$2:$B$4957,$A9)/$B9,"") -> 0.24486601
A10: TN | B10: =SUM(C10:G10) -> 3760723 | C10: =SUMIFS(Plans!$AA$2:$AA$4957,Plans!$A$2:$A$4957,Fixability!$C$3,Plans!$B$2:$B$4957,$A10) -> 1068753 | D10: =SUMIFS(Plans!$AB$2:$AB$4957,Plans!$A$2:$A$4957,Fixability!$C$3,Plans!$B$2:$B$4957,$A10) -> 271545 | E10: =SUMIFS(Plans!$AC$2:$AC$4957,Plans!$A$2:$A$4957,Fixability!$C$3,Plans!$B$2:$B$4957,$A10) -> 1075308 | F10: =SUMIFS(Plans!$AD$2:$AD$4957,Plans!$A$2:$A$4957,Fixability!$C$3,Plans!$B$2:$B$4957,$A10) -> 575712 | G10: =SUMIFS(Plans!$AE$2:$AE$4957,Plans!$A$2:$A$4957,Fixability!$C$3,Plans!$B$2:$B$4957,$A10) -> 769405 | H10: =IFERROR((C10+D10)/B10,"") -> 0.3563937 | I10: =IFERROR(SUMIFS(Plans!$Q$2:$Q$4957,Plans!$A$2:$A$4957,Fixability!$C$3,Plans!$B$2:$B$4957,$A10)/$B10,"") -> 0.28418817 | J10: =IFERROR(SUMIFS(Plans!$R$2:$R$4957,Plans!$A$2:$A$4957,Fixability!$C$3,Plans!$B$2:$B$4957,$A10)/$B10,"") -> 0.059653689 | K10: =IFERROR(SUMIFS(Plans!$S$2:$S$4957,Plans!$A$2:$A$4957,Fixability!$C$3,Plans!$B$2:$B$4957,$A10)/$B10,"") -> 0.012551842 | L10: =IFERROR(SUMIFS(Plans!$T$2:$T$4957,Plans!$A$2:$A$4957,Fixability!$C$3,Plans!$B$2:$B$4957,$A10)/$B10,"") -> 0.091541174 | M10: =IFERROR(SUMIFS(Plans!$U$2:$U$4957,Plans!$A$2:$A$4957,Fixability!$C$3,Plans!$B$2:$B$4957,$A10)/$B10,"") -> 0.068225445 | N10: =IFERROR(SUMIFS(Plans!$V$2:$V$4957,Plans!$A$2:$A$4957,Fixability!$C$3,Plans!$B$2:$B$4957,$A10)/$B10,"") -> 0.12616457 | O10: =IFERROR(SUMIFS(Plans!$W$2:$W$4957,Plans!$A$2:$A$4957,Fixability!$C$3,Plans!$B$2:$B$4957,$A10)/$B10,"") -> 0.035837524 | P10: =IFERROR(SUMIFS(Plans!$X$2:$X$4957,Plans!$A$2:$A$4957,Fixability!$C$3,Plans!$B$2:$B$4957,$A10)/$B10,"") -> 0.11671984 | Q10: =IFERROR(SUMIFS(Plans!$Y$2:$Y$4957,Plans!$A$2:$A$4957,Fixability!$C$3,Plans!$B$2:$B$4957,$A10)/$B10,"") -> 0.00052808994 | R10: =IFERROR(SUMIFS(Plans!$Z$2:$Z$4957,Plans!$A$2:$A$4957,Fixability!$C$3,Plans!$B$2:$B$4957,$A10)/$B10,"") -> 0.20458965
A11: OH | B11: =SUM(C11:G11) -> 3605643 | C11: =SUMIFS(Plans!$AA$2:$AA$4957,Plans!$A$2:$A$4957,Fixability!$C$3,Plans!$B$2:$B$4957,$A11) -> 951084 | D11: =SUMIFS(Plans!$AB$2:$AB$4957,Plans!$A$2:$A$4957,Fixability!$C$3,Plans!$B$2:$B$4957,$A11) -> 404913 | E11: =SUMIFS(Plans!$AC$2:$AC$4957,Plans!$A$2:$A$4957,Fixability!$C$3,Plans!$B$2:$B$4957,$A11) -> 1221570 | F11: =SUMIFS(Plans!$AD$2:$AD$4957,Plans!$A$2:$A$4957,Fixability!$C$3,Plans!$B$2:$B$4957,$A11) -> 669726 | G11: =SUMIFS(Plans!$AE$2:$AE$4957,Plans!$A$2:$A$4957,Fixability!$C$3,Plans!$B$2:$B$4957,$A11) -> 358350 | H11: =IFERROR((C11+D11)/B11,"") -> 0.37607633 | I11: =IFERROR(SUMIFS(Plans!$Q$2:$Q$4957,Plans!$A$2:$A$4957,Fixability!$C$3,Plans!$B$2:$B$4957,$A11)/$B11,"") -> 0.26377653 | J11: =IFERROR(SUMIFS(Plans!$R$2:$R$4957,Plans!$A$2:$A$4957,Fixability!$C$3,Plans!$B$2:$B$4957,$A11)/$B11,"") -> 0.10058622 | K11: =IFERROR(SUMIFS(Plans!$S$2:$S$4957,Plans!$A$2:$A$4957,Fixability!$C$3,Plans!$B$2:$B$4957,$A11)/$B11,"") -> 0.011713583 | L11: =IFERROR(SUMIFS(Plans!$T$2:$T$4957,Plans!$A$2:$A$4957,Fixability!$C$3,Plans!$B$2:$B$4957,$A11)/$B11,"") -> 0.11759761 | M11: =IFERROR(SUMIFS(Plans!$U$2:$U$4957,Plans!$A$2:$A$4957,Fixability!$C$3,Plans!$B$2:$B$4957,$A11)/$B11,"") -> 0.069484417 | N11: =IFERROR(SUMIFS(Plans!$V$2:$V$4957,Plans!$A$2:$A$4957,Fixability!$C$3,Plans!$B$2:$B$4957,$A11)/$B11,"") -> 0.15171191 | O11: =IFERROR(SUMIFS(Plans!$W$2:$W$4957,Plans!$A$2:$A$4957,Fixability!$C$3,Plans!$B$2:$B$4957,$A11)/$B11,"") -> 0.083672455 | P11: =IFERROR(SUMIFS(Plans!$X$2:$X$4957,Plans!$A$2:$A$4957,Fixability!$C$3,Plans!$B$2:$B$4957,$A11)/$B11,"") -> 0.097896825 | Q11: =IFERROR(SUMIFS(Plans!$Y$2:$Y$4957,Plans!$A$2:$A$4957,Fixability!$C$3,Plans!$B$2:$B$4957,$A11)/$B11,"") -> 0.0041745675 | R11: =IFERROR(SUMIFS(Plans!$Z$2:$Z$4957,Plans!$A$2:$A$4957,Fixability!$C$3,Plans!$B$2:$B$4957,$A11)/$B11,"") -> 0.099385879
A12: AR | B12: =SUM(C12:G12) -> 3119026 | C12: =SUMIFS(Plans!$AA$2:$AA$4957,Plans!$A$2:$A$4957,Fixability!$C$3,Plans!$B$2:$B$4957,$A12) -> 707653 | D12: =SUMIFS(Plans!$AB$2:$AB$4957,Plans!$A$2:$A$4957,Fixability!$C$3,Plans!$B$2:$B$4957,$A12) -> 192732 | E12: =SUMIFS(Plans!$AC$2:$AC$4957,Plans!$A$2:$A$4957,Fixability!$C$3,Plans!$B$2:$B$4957,$A12) -> 759708 | F12: =SUMIFS(Plans!$AD$2:$AD$4957,Plans!$A$2:$A$4957,Fixability!$C$3,Plans!$B$2:$B$4957,$A12) -> 838316 | G12: =SUMIFS(Plans!$AE$2:$AE$4957,Plans!$A$2:$A$4957,Fixability!$C$3,Plans!$B$2:$B$4957,$A12) -> 620617 | H12: =IFERROR((C12+D12)/B12,"") -> 0.28867505 | I12: =IFERROR(SUMIFS(Plans!$Q$2:$Q$4957,Plans!$A$2:$A$4957,Fixability!$C$3,Plans!$B$2:$B$4957,$A12)/$B12,"") -> 0.22688269 | J12: =IFERROR(SUMIFS(Plans!$R$2:$R$4957,Plans!$A$2:$A$4957,Fixability!$C$3,Plans!$B$2:$B$4957,$A12)/$B12,"") -> 0.059442595 | K12: =IFERROR(SUMIFS(Plans!$S$2:$S$4957,Plans!$A$2:$A$4957,Fixability!$C$3,Plans!$B$2:$B$4957,$A12)/$B12,"") -> 0.002349772 | L12: =IFERROR(SUMIFS(Plans!$T$2:$T$4957,Plans!$A$2:$A$4957,Fixability!$C$3,Plans!$B$2:$B$4957,$A12)/$B12,"") -> 0.13731338 | M12: =IFERROR(SUMIFS(Plans!$U$2:$U$4957,Plans!$A$2:$A$4957,Fixability!$C$3,Plans!$B$2:$B$4957,$A12)/$B12,"") -> 0.094380746 | N12: =IFERROR(SUMIFS(Plans!$V$2:$V$4957,Plans!$A$2:$A$4957,Fixability!$C$3,Plans!$B$2:$B$4957,$A12)/$B12,"") -> 0.011878067 | O12: =IFERROR(SUMIFS(Plans!$W$2:$W$4957,Plans!$A$2:$A$4957,Fixability!$C$3,Plans!$B$2:$B$4957,$A12)/$B12,"") -> 0.18423796 | P12: =IFERROR(SUMIFS(Plans!$X$2:$X$4957,Plans!$A$2:$A$4957,Fixability!$C$3,Plans!$B$2:$B$4957,$A12)/$B12,"") -> 0.084536968 | Q12: =IFERROR(SUMIFS(Plans!$Y$2:$Y$4957,Plans!$A$2:$A$4957,Fixability!$C$3,Plans!$B$2:$B$4957,$A12)/$B12,"") -> 0 | R12: =IFERROR(SUMIFS(Plans!$Z$2:$Z$4957,Plans!$A$2:$A$4957,Fixability!$C$3,Plans!$B$2:$B$4957,$A12)/$B12,"") -> 0.19897782
A13: OK | B13: =SUM(C13:G13) -> 2365896 | C13: =SUMIFS(Plans!$AA$2:$AA$4957,Plans!$A$2:$A$4957,Fixability!$C$3,Plans!$B$2:$B$4957,$A13) -> 564496 | D13: =SUMIFS(Plans!$AB$2:$AB$4957,Plans!$A$2:$A$4957,Fixability!$C$3,Plans!$B$2:$B$4957,$A13) -> 86168 | E13: =SUMIFS(Plans!$AC$2:$AC$4957,Plans!$A$2:$A$4957,Fixability!$C$3,Plans!$B$2:$B$4957,$A13) -> 546675 | F13: =SUMIFS(Plans!$AD$2:$AD$4957,Plans!$A$2:$A$4957,Fixability!$C$3,Plans!$B$2:$B$4957,$A13) -> 389902 | G13: =SUMIFS(Plans!$AE$2:$AE$4957,Plans!$A$2:$A$4957,Fixability!$C$3,Plans!$B$2:$B$4957,$A13) -> 778655 | H13: =IFERROR((C13+D13)/B13,"") -> 0.27501801 | I13: =IFERROR(SUMIFS(Plans!$Q$2:$Q$4957,Plans!$A$2:$A$4957,Fixability!$C$3,Plans!$B$2:$B$4957,$A13)/$B13,"") -> 0.23859713 | J13: =IFERROR(SUMIFS(Plans!$R$2:$R$4957,Plans!$A$2:$A$4957,Fixability!$C$3,Plans!$B$2:$B$4957,$A13)/$B13,"") -> 0.034070813 | K13: =IFERROR(SUMIFS(Plans!$S$2:$S$4957,Plans!$A$2:$A$4957,Fixability!$C$3,Plans!$B$2:$B$4957,$A13)/$B13,"") -> 0.002350061 | L13: =IFERROR(SUMIFS(Plans!$T$2:$T$4957,Plans!$A$2:$A$4957,Fixability!$C$3,Plans!$B$2:$B$4957,$A13)/$B13,"") -> 0.1094748 | M13: =IFERROR(SUMIFS(Plans!$U$2:$U$4957,Plans!$A$2:$A$4957,Fixability!$C$3,Plans!$B$2:$B$4957,$A13)/$B13,"") -> 0.091860335 | N13: =IFERROR(SUMIFS(Plans!$V$2:$V$4957,Plans!$A$2:$A$4957,Fixability!$C$3,Plans!$B$2:$B$4957,$A13)/$B13,"") -> 0.02972954 | O13: =IFERROR(SUMIFS(Plans!$W$2:$W$4957,Plans!$A$2:$A$4957,Fixability!$C$3,Plans!$B$2:$B$4957,$A13)/$B13,"") -> 0.020143743 | P13: =IFERROR(SUMIFS(Plans!$X$2:$X$4957,Plans!$A$2:$A$4957,Fixability!$C$3,Plans!$B$2:$B$4957,$A13)/$B13,"") -> 0.14322058 | Q13: =IFERROR(SUMIFS(Plans!$Y$2:$Y$4957,Plans!$A$2:$A$4957,Fixability!$C$3,Plans!$B$2:$B$4957,$A13)/$B13,"") -> 0.001436665 | R13: =IFERROR(SUMIFS(Plans!$Z$2:$Z$4957,Plans!$A$2:$A$4957,Fixability!$C$3,Plans!$B$2:$B$4957,$A13)/$B13,"") -> 0.32911633
A14: UT | B14: =SUM(C14:G14) -> 2306364 | C14: =SUMIFS(Plans!$AA$2:$AA$4957,Plans!$A$2:$A$4957,Fixability!$C$3,Plans!$B$2:$B$4957,$A14) -> 282148 | D14: =SUMIFS(Plans!$AB$2:$AB$4957,Plans!$A$2:$A$4957,Fixability!$C$3,Plans!$B$2:$B$4957,$A14) -> 26211 | E14: =SUMIFS(Plans!$AC$2:$AC$4957,Plans!$A$2:$A$4957,Fixability!$C$3,Plans!$B$2:$B$4957,$A14) -> 319884 | F14: =SUMIFS(Plans!$AD$2:$AD$4957,Plans!$A$2:$A$4957,Fixability!$C$3,Plans!$B$2:$B$4957,$A14) -> 345017 | G14: =SUMIFS(Plans!$AE$2:$AE$4957,Plans!$A$2:$A$4957,Fixability!$C$3,Plans!$B$2:$B$4957,$A14) -> 1333104 | H14: =IFERROR((C14+D14)/B14,"") -> 0.13369919 | I14: =IFERROR(SUMIFS(Plans!$Q$2:$Q$4957,Plans!$A$2:$A$4957,Fixability!$C$3,Plans!$B$2:$B$4957,$A14)/$B14,"") -> 0.12233455 | J14: =IFERROR(SUMIFS(Plans!$R$2:$R$4957,Plans!$A$2:$A$4957,Fixability!$C$3,Plans!$B$2:$B$4957,$A14)/$B14,"") -> 0.0092530927 | K14: =IFERROR(SUMIFS(Plans!$S$2:$S$4957,Plans!$A$2:$A$4957,Fixability!$C$3,Plans!$B$2:$B$4957,$A14)/$B14,"") -> 0.0021115487 | L14: =IFERROR(SUMIFS(Plans!$T$2:$T$4957,Plans!$A$2:$A$4957,Fixability!$C$3,Plans!$B$2:$B$4957,$A14)/$B14,"") -> 0.042494593 | M14: =IFERROR(SUMIFS(Plans!$U$2:$U$4957,Plans!$A$2:$A$4957,Fixability!$C$3,Plans!$B$2:$B$4957,$A14)/$B14,"") -> 0.046968302 | N14: =IFERROR(SUMIFS(Plans!$V$2:$V$4957,Plans!$A$2:$A$4957,Fixability!$C$3,Plans!$B$2:$B$4957,$A14)/$B14,"") -> 0.049233339 | O14: =IFERROR(SUMIFS(Plans!$W$2:$W$4957,Plans!$A$2:$A$4957,Fixability!$C$3,Plans!$B$2:$B$4957,$A14)/$B14,"") -> 0.026315447 | P14: =IFERROR(SUMIFS(Plans!$X$2:$X$4957,Plans!$A$2:$A$4957,Fixability!$C$3,Plans!$B$2:$B$4957,$A14)/$B14,"") -> 0.11989825 | Q14: =IFERROR(SUMIFS(Plans!$Y$2:$Y$4957,Plans!$A$2:$A$4957,Fixability!$C$3,Plans!$B$2:$B$4957,$A14)/$B14,"") -> 0.0033797787 | R14: =IFERROR(SUMIFS(Plans!$Z$2:$Z$4957,Plans!$A$2:$A$4957,Fixability!$C$3,Plans!$B$2:$B$4957,$A14)/$B14,"") -> 0.5780111
A15: MS | B15: =SUM(C15:G15) -> 2186942 | C15: =SUMIFS(Plans!$AA$2:$AA$4957,Plans!$A$2:$A$4957,Fixability!$C$3,Plans!$B$2:$B$4957,$A15) -> 454259 | D15: =SUMIFS(Plans!$AB$2:$AB$4957,Plans!$A$2:$A$4957,Fixability!$C$3,Plans!$B$2:$B$4957,$A15) -> 217897 | E15: =SUMIFS(Plans!$AC$2:$AC$4957,Plans!$A$2:$A$4957,Fixability!$C$3,Plans!$B$2:$B$4957,$A15) -> 566971 | F15: =SUMIFS(Plans!$AD$2:$AD$4957,Plans!$A$2:$A$4957,Fixability!$C$3,Plans!$B$2:$B$4957,$A15) -> 320572 | G15: =SUMIFS(Plans!$AE$2:$AE$4957,Plans!$A$2:$A$4957,Fixability!$C$3,Plans!$B$2:$B$4957,$A15) -> 627243 | H15: =IFERROR((C15+D15)/B15,"") -> 0.30734971 | I15: =IFERROR(SUMIFS(Plans!$Q$2:$Q$4957,Plans!$A$2:$A$4957,Fixability!$C$3,Plans!$B$2:$B$4957,$A15)/$B15,"") -> 0.20771424 | J15: =IFERROR(SUMIFS(Plans!$R$2:$R$4957,Plans!$A$2:$A$4957,Fixability!$C$3,Plans!$B$2:$B$4957,$A15)/$B15,"") -> 0.084876508 | K15: =IFERROR(SUMIFS(Plans!$S$2:$S$4957,Plans!$A$2:$A$4957,Fixability!$C$3,Plans!$B$2:$B$4957,$A15)/$B15,"") -> 0.014758965 | L15: =IFERROR(SUMIFS(Plans!$T$2:$T$4957,Plans!$A$2:$A$4957,Fixability!$C$3,Plans!$B$2:$B$4957,$A15)/$B15,"") -> 0.077963659 | M15: =IFERROR(SUMIFS(Plans!$U$2:$U$4957,Plans!$A$2:$A$4957,Fixability!$C$3,Plans!$B$2:$B$4957,$A15)/$B15,"") -> 0.07327995 | N15: =IFERROR(SUMIFS(Plans!$V$2:$V$4957,Plans!$A$2:$A$4957,Fixability!$C$3,Plans!$B$2:$B$4957,$A15)/$B15,"") -> 0.10800927 | O15: =IFERROR(SUMIFS(Plans!$W$2:$W$4957,Plans!$A$2:$A$4957,Fixability!$C$3,Plans!$B$2:$B$4957,$A15)/$B15,"") -> 0.046530726 | P15: =IFERROR(SUMIFS(Plans!$X$2:$X$4957,Plans!$A$2:$A$4957,Fixability!$C$3,Plans!$B$2:$B$4957,$A15)/$B15,"") -> 0.1000278 | Q15: =IFERROR(SUMIFS(Plans!$Y$2:$Y$4957,Plans!$A$2:$A$4957,Fixability!$C$3,Plans!$B$2:$B$4957,$A15)/$B15,"") -> 2.6063791e-05 | R15: =IFERROR(SUMIFS(Plans!$Z$2:$Z$4957,Plans!$A$2:$A$4957,Fixability!$C$3,Plans!$B$2:$B$4957,$A15)/$B15,"") -> 0.28681282
A16: MO | B16: =SUM(C16:G16) -> 1823967 | C16: =SUMIFS(Plans!$AA$2:$AA$4957,Plans!$A$2:$A$4957,Fixability!$C$3,Plans!$B$2:$B$4957,$A16) -> 456519 | D16: =SUMIFS(Plans!$AB$2:$AB$4957,Plans!$A$2:$A$4957,Fixability!$C$3,Plans!$B$2:$B$4957,$A16) -> 127816 | E16: =SUMIFS(Plans!$AC$2:$AC$4957,Plans!$A$2:$A$4957,Fixability!$C$3,Plans!$B$2:$B$4957,$A16) -> 683065 | F16: =SUMIFS(Plans!$AD$2:$AD$4957,Plans!$A$2:$A$4957,Fixability!$C$3,Plans!$B$2:$B$4957,$A16) -> 331656 | G16: =SUMIFS(Plans!$AE$2:$AE$4957,Plans!$A$2:$A$4957,Fixability!$C$3,Plans!$B$2:$B$4957,$A16) -> 224911 | H16: =IFERROR((C16+D16)/B16,"") -> 0.3203649 | I16: =IFERROR(SUMIFS(Plans!$Q$2:$Q$4957,Plans!$A$2:$A$4957,Fixability!$C$3,Plans!$B$2:$B$4957,$A16)/$B16,"") -> 0.25028907 | J16: =IFERROR(SUMIFS(Plans!$R$2:$R$4957,Plans!$A$2:$A$4957,Fixability!$C$3,Plans!$B$2:$B$4957,$A16)/$B16,"") -> 0.067477646 | K16: =IFERROR(SUMIFS(Plans!$S$2:$S$4957,Plans!$A$2:$A$4957,Fixability!$C$3,Plans!$B$2:$B$4957,$A16)/$B16,"") -> 0.002598183 | L16: =IFERROR(SUMIFS(Plans!$T$2:$T$4957,Plans!$A$2:$A$4957,Fixability!$C$3,Plans!$B$2:$B$4957,$A16)/$B16,"") -> 0.11255851 | M16: =IFERROR(SUMIFS(Plans!$U$2:$U$4957,Plans!$A$2:$A$4957,Fixability!$C$3,Plans!$B$2:$B$4957,$A16)/$B16,"") -> 0.095611927 | N16: =IFERROR(SUMIFS(Plans!$V$2:$V$4957,Plans!$A$2:$A$4957,Fixability!$C$3,Plans!$B$2:$B$4957,$A16)/$B16,"") -> 0.16632373 | O16: =IFERROR(SUMIFS(Plans!$W$2:$W$4957,Plans!$A$2:$A$4957,Fixability!$C$3,Plans!$B$2:$B$4957,$A16)/$B16,"") -> 0.054354602 | P16: =IFERROR(SUMIFS(Plans!$X$2:$X$4957,Plans!$A$2:$A$4957,Fixability!$C$3,Plans!$B$2:$B$4957,$A16)/$B16,"") -> 0.12714265 | Q16: =IFERROR(SUMIFS(Plans!$Y$2:$Y$4957,Plans!$A$2:$A$4957,Fixability!$C$3,Plans!$B$2:$B$4957,$A16)/$B16,"") -> 0.00033498413 | R16: =IFERROR(SUMIFS(Plans!$Z$2:$Z$4957,Plans!$A$2:$A$4957,Fixability!$C$3,Plans!$B$2:$B$4957,$A16)/$B16,"") -> 0.1233087
... A34: ND | B34: =SUM(C34:G34) -> 156713 | C34: =SUMIFS(Plans!$AA$2:$AA$4957,Plans!$A$2:$A$4957,Fixability!$C$3,Plans!$B$2:$B$4957,$A34) -> 10624 | D34: =SUMIFS(Plans!$AB$2:$AB$4957,Plans!$A$2:$A$4957,Fixability!$C$3,Plans!$B$2:$B$4957,$A34) -> 30484 | E34: =SUMIFS(Plans!$AC$2:$AC$4957,Plans!$A$2:$A$4957,Fixability!$C$3,Plans!$B$2:$B$4957,$A34) -> 22214 | F34: =SUMIFS(Plans!$AD$2:$AD$4957,Plans!$A$2:$A$4957,Fixability!$C$3,Plans!$B$2:$B$4957,$A34) -> 8530 | G34: =SUMIFS(Plans!$AE$2:$AE$4957,Plans!$A$2:$A$4957,Fixability!$C$3,Plans!$B$2:$B$4957,$A34) -> 84861 | H34: =IFERROR((C34+D34)/B34,"") -> 0.26231391 | I34: =IFERROR(SUMIFS(Plans!$Q$2:$Q$4957,Plans!$A$2:$A$4957,Fixability!$C$3,Plans!$B$2:$B$4957,$A34)/$B34,"") -> 0.067792717 | J34: =IFERROR(SUMIFS(Plans!$R$2:$R$4957,Plans!$A$2:$A$4957,Fixability!$C$3,Plans!$B$2:$B$4957,$A34)/$B34,"") -> 0.16911807 | K34: =IFERROR(SUMIFS(Plans!$S$2:$S$4957,Plans!$A$2:$A$4957,Fixability!$C$3,Plans!$B$2:$B$4957,$A34)/$B34,"") -> 0.025403125 | L34: =IFERROR(SUMIFS(Plans!$T$2:$T$4957,Plans!$A$2:$A$4957,Fixability!$C$3,Plans!$B$2:$B$4957,$A34)/$B34,"") -> 0.024624632 | M34: =IFERROR(SUMIFS(Plans!$U$2:$U$4957,Plans!$A$2:$A$4957,Fixability!$C$3,Plans!$B$2:$B$4957,$A34)/$B34,"") -> 0.029965606 | N34: =IFERROR(SUMIFS(Plans!$V$2:$V$4957,Plans!$A$2:$A$4957,Fixability!$C$3,Plans!$B$2:$B$4957,$A34)/$B34,"") -> 0.087159329 | O34: =IFERROR(SUMIFS(Plans!$W$2:$W$4957,Plans!$A$2:$A$4957,Fixability!$C$3,Plans!$B$2:$B$4957,$A34)/$B34,"") -> 0.016022921 | P34: =IFERROR(SUMIFS(Plans!$X$2:$X$4957,Plans!$A$2:$A$4957,Fixability!$C$3,Plans!$B$2:$B$4957,$A34)/$B34,"") -> 0.032039461 | Q34: =IFERROR(SUMIFS(Plans!$Y$2:$Y$4957,Plans!$A$2:$A$4957,Fixability!$C$3,Plans!$B$2:$B$4957,$A34)/$B34,"") -> 0.0063683294 | R34: =IFERROR(SUMIFS(Plans!$Z$2:$Z$4957,Plans!$A$2:$A$4957,Fixability!$C$3,Plans!$B$2:$B$4957,$A34)/$B34,"") -> 0.54150581
A35: All | B35: =SUM(B5:B34) -> 87173324 | C35: =SUM(C5:C34) -> 19612209 | D35: =SUM(D5:D34) -> 3968921 | E35: =SUM(E5:E34) -> 21601333 | F35: =SUM(F5:F34) -> 13877230 | G35: =SUM(G5:G34) -> 28113631 | H35: =IFERROR((C35+D35)/B35,"") -> 0.27050856 | I35: =IFERROR(SUMIFS(Plans!$Q$2:$Q$4957,Plans!$A$2:$A$4957,Fixability!$C$3)/$B35,"") -> 0.22497948 | J35: =IFERROR(SUMIFS(Plans!$R$2:$R$4957,Plans!$A$2:$A$4957,Fixability!$C$3)/$B35,"") -> 0.041234254 | K35: =IFERROR(SUMIFS(Plans!$S$2:$S$4957,Plans!$A$2:$A$4957,Fixability!$C$3)/$B35,"") -> 0.004294823 | L35: =IFERROR(SUMIFS(Plans!$T$2:$T$4957,Plans!$A$2:$A$4957,Fixability!$C$3)/$B35,"") -> 0.083794556 | M35: =IFERROR(SUMIFS(Plans!$U$2:$U$4957,Plans!$A$2:$A$4957,Fixability!$C$3)/$B35,"") -> 0.065720885 | N35: =IFERROR(SUMIFS(Plans!$V$2:$V$4957,Plans!$A$2:$A$4957,Fixability!$C$3)/$B35,"") -> 0.098282073 | O35: =IFERROR(SUMIFS(Plans!$W$2:$W$4957,Plans!$A$2:$A$4957,Fixability!$C$3)/$B35,"") -> 0.041830538 | P35: =IFERROR(SUMIFS(Plans!$X$2:$X$4957,Plans!$A$2:$A$4957,Fixability!$C$3)/$B35,"") -> 0.11619508 | Q35: =IFERROR(SUMIFS(Plans!$Y$2:$Y$4957,Plans!$A$2:$A$4957,Fixability!$C$3)/$B35,"") -> 0.0011656318 | R35: =IFERROR(SUMIFS(Plans!$Z$2:$Z$4957,Plans!$A$2:$A$4957,Fixability!$C$3)/$B35,"") -> 0.32250268

Sheet By Plan Type
A1: Denial reasons by Plan Type — market: | D1: =Fixability!$C$3 -> Individual Medical
A2: Counts by fixability tier, then each reason as a share of that row's classified denials. Change the market on the Fixability tab.
A4: Plan Type | B4: Denials With Reason | C4: Tier 1 High | D4: Tier 2 Medium-High | E4: Tier 3 Medium | F4: Tier 4 Low | G4: Tier 5 Unknown | H4: % Fixable (High + Med-High) | I4: % Administrative | J4: % Not medically necessary (medical) | K4: % Not medically necessary (behavioral health) | L4: % Referral required | M4: % Member not covered | N4: % Out-of-network | O4: % Benefit limit reached | P4: % Service excluded | Q4: % Experimental / cosmetic | R4: % Other / unspecified
A5: PPO | B5: =SUM(C5:G5) -> 10772145 | C5: =SUMIFS(Plans!$AA$2:$AA$4957,Plans!$A$2:$A$4957,Fixability!$C$3,Plans!$G$2:$G$4957,$A5) -> 2451175 | D5: =SUMIFS(Plans!$AB$2:$AB$4957,Plans!$A$2:$A$4957,Fixability!$C$3,Plans!$G$2:$G$4957,$A5) -> 354899 | E5: =SUMIFS(Plans!$AC$2:$AC$4957,Plans!$A$2:$A$4957,Fixability!$C$3,Plans!$G$2:$G$4957,$A5) -> 2376345 | F5: =SUMIFS(Plans!$AD$2:$AD$4957,Plans!$A$2:$A$4957,Fixability!$C$3,Plans!$G$2:$G$4957,$A5) -> 2700208 | G5: =SUMIFS(Plans!$AE$2:$AE$4957,Plans!$A$2:$A$4957,Fixability!$C$3,Plans!$G$2:$G$4957,$A5) -> 2889518 | H5: =IFERROR((C5+D5)/B5,"") -> 0.26049352 | I5: =IFERROR(SUMIFS(Plans!$Q$2:$Q$4957,Plans!$A$2:$A$4957,Fixability!$C$3,Plans!$G$2:$G$4957,$A5)/$B5,"") -> 0.22754753 | J5: =IFERROR(SUMIFS(Plans!$R$2:$R$4957,Plans!$A$2:$A$4957,Fixability!$C$3,Plans!$G$2:$G$4957,$A5)/$B5,"") -> 0.030848267 | K5: =IFERROR(SUMIFS(Plans!$S$2:$S$4957,Plans!$A$2:$A$4957,Fixability!$C$3,Plans!$G$2:$G$4957,$A5)/$B5,"") -> 0.0020977252 | L5: =IFERROR(SUMIFS(Plans!$T$2:$T$4957,Plans!$A$2:$A$4957,Fixability!$C$3,Plans!$G$2:$G$4957,$A5)/$B5,"") -> 0.079689328 | M5: =IFERROR(SUMIFS(Plans!$U$2:$U$4957,Plans!$A$2:$A$4957,Fixability!$C$3,Plans!$G$2:$G$4957,$A5)/$B5,"") -> 0.11043065 | N5: =IFERROR(SUMIFS(Plans!$V$2:$V$4957,Plans!$A$2:$A$4957,Fixability!$C$3,Plans!$G$2:$G$4957,$A5)/$B5,"") -> 0.03048093 | O5: =IFERROR(SUMIFS(Plans!$W$2:$W$4957,Plans!$A$2:$A$4957,Fixability!$C$3,Plans!$G$2:$G$4957,$A5)/$B5,"") -> 0.088521367 | P5: =IFERROR(SUMIFS(Plans!$X$2:$X$4957,Plans!$A$2:$A$4957,Fixability!$C$3,Plans!$G$2:$G$4957,$A5)/$B5,"") -> 0.16091902 | Q5: =IFERROR(SUMIFS(Plans!$Y$2:$Y$4957,Plans!$A$2:$A$4957,Fixability!$C$3,Plans!$G$2:$G$4957,$A5)/$B5,"") -> 0.0012253827 | R5: =IFERROR(SUMIFS(Plans!$Z$2:$Z$4957,Plans!$A$2:$A$4957,Fixability!$C$3,Plans!$G$2:$G$4957,$A5)/$B5,"") -> 0.2682398
A6: EPO | B6: =SUM(C6:G6) -> 24537628 | C6: =SUMIFS(Plans!$AA$2:$AA$4957,Plans!$A$2:$A$4957,Fixability!$C$3,Plans!$G$2:$G$4957,$A6) -> 6620195 | D6: =SUMIFS(Plans!$AB$2:$AB$4957,Plans!$A$2:$A$4957,Fixability!$C$3,Plans!$G$2:$G$4957,$A6) -> 1371995 | E6: =SUMIFS(Plans!$AC$2:$AC$4957,Plans!$A$2:$A$4957,Fixability!$C$3,Plans!$G$2:$G$4957,$A6) -> 6722238 | F6: =SUMIFS(Plans!$AD$2:$AD$4957,Plans!$A$2:$A$4957,Fixability!$C$3,Plans!$G$2:$G$4957,$A6) -> 3476768 | G6: =SUMIFS(Plans!$AE$2:$AE$4957,Plans!$A$2:$A$4957,Fixability!$C$3,Plans!$G$2:$G$4957,$A6) -> 6346432 | H6: =IFERROR((C6+D6)/B6,"") -> 0.3257116 | I6: =IFERROR(SUMIFS(Plans!$Q$2:$Q$4957,Plans!$A$2:$A$4957,Fixability!$C$3,Plans!$G$2:$G$4957,$A6)/$B6,"") -> 0.26979768 | J6: =IFERROR(SUMIFS(Plans!$R$2:$R$4957,Plans!$A$2:$A$4957,Fixability!$C$3,Plans!$G$2:$G$4957,$A6)/$B6,"") -> 0.049585681 | K6: =IFERROR(SUMIFS(Plans!$S$2:$S$4957,Plans!$A$2:$A$4957,Fixability!$C$3,Plans!$G$2:$G$4957,$A6)/$B6,"") -> 0.00632824 | L6: =IFERROR(SUMIFS(Plans!$T$2:$T$4957,Plans!$A$2:$A$4957,Fixability!$C$3,Plans!$G$2:$G$4957,$A6)/$B6,"") -> 0.079846878 | M6: =IFERROR(SUMIFS(Plans!$U$2:$U$4957,Plans!$A$2:$A$4957,Fixability!$C$3,Plans!$G$2:$G$4957,$A6)/$B6,"") -> 0.065781012 | N6: =IFERROR(SUMIFS(Plans!$V$2:$V$4957,Plans!$A$2:$A$4957,Fixability!$C$3,Plans!$G$2:$G$4957,$A6)/$B6,"") -> 0.12832842 | O6: =IFERROR(SUMIFS(Plans!$W$2:$W$4957,Plans!$A$2:$A$4957,Fixability!$C$3,Plans!$G$2:$G$4957,$A6)/$B6,"") -> 0.048131343 | P6: =IFERROR(SUMIFS(Plans!$X$2:$X$4957,Plans!$A$2:$A$4957,Fixability!$C$3,Plans!$G$2:$G$4957,$A6)/$B6,"") -> 0.092945088 | Q6: =IFERROR(SUMIFS(Plans!$Y$2:$Y$4957,Plans!$A$2:$A$4957,Fixability!$C$3,Plans!$G$2:$G$4957,$A6)/$B6,"") -> 0.00061485161 | R6: =IFERROR(SUMIFS(Plans!$Z$2:$Z$4957,Plans!$A$2:$A$4957,Fixability!$C$3,Plans!$G$2:$G$4957,$A6)/$B6,"") -> 0.25864081
A7: HMO | B7: =SUM(C7:G7) -> 48033806 | C7: =SUMIFS(Plans!$AA$2:$AA$4957,Plans!$A$2:$A$4957,Fixability!$C$3,Plans!$G$2:$G$4957,$A7) -> 9736506 | D7: =SUMIFS(Plans!$AB$2:$AB$4957,Plans!$A$2:$A$4957,Fixability!$C$3,Plans!$G$2:$G$4957,$A7) -> 2189272 | E7: =SUMIFS(Plans!$AC$2:$AC$4957,Plans!$A$2:$A$4957,Fixability!$C$3,Plans!$G$2:$G$4957,$A7) -> 12021127 | F7: =SUMIFS(Plans!$AD$2:$AD$4957,Plans!$A$2:$A$4957,Fixability!$C$3,Plans!$G$2:$G$4957,$A7) -> 7130628 | G7: =SUMIFS(Plans!$AE$2:$AE$4957,Plans!$A$2:$A$4957,Fixability!$C$3,Plans!$G$2:$G$4957,$A7) -> 16956273 | H7: =IFERROR((C7+D7)/B7,"") -> 0.24827885 | I7: =IFERROR(SUMIFS(Plans!$Q$2:$Q$4957,Plans!$A$2:$A$4957,Fixability!$C$3,Plans!$G$2:$G$4957,$A7)/$B7,"") -> 0.20270111 | J7: =IFERROR(SUMIFS(Plans!$R$2:$R$4957,Plans!$A$2:$A$4957,Fixability!$C$3,Plans!$G$2:$G$4957,$A7)/$B7,"") -> 0.04160016 | K7: =IFERROR(SUMIFS(Plans!$S$2:$S$4957,Plans!$A$2:$A$4957,Fixability!$C$3,Plans!$G$2:$G$4957,$A7)/$B7,"") -> 0.0039775736 | L7: =IFERROR(SUMIFS(Plans!$T$2:$T$4957,Plans!$A$2:$A$4957,Fixability!$C$3,Plans!$G$2:$G$4957,$A7)/$B7,"") -> 0.090829176 | M7: =IFERROR(SUMIFS(Plans!$U$2:$U$4957,Plans!$A$2:$A$4957,Fixability!$C$3,Plans!$G$2:$G$4957,$A7)/$B7,"") -> 0.054448652 | N7: =IFERROR(SUMIFS(Plans!$V$2:$V$4957,Plans!$A$2:$A$4957,Fixability!$C$3,Plans!$G$2:$G$4957,$A7)/$B7,"") -> 0.10498606 | O7: =IFERROR(SUMIFS(Plans!$W$2:$W$4957,Plans!$A$2:$A$4957,Fixability!$C$3,Plans!$G$2:$G$4957,$A7)/$B7,"") -> 0.028257036 | P7: =IFERROR(SUMIFS(Plans!$X$2:$X$4957,Plans!$A$2:$A$4957,Fixability!$C$3,Plans!$G$2:$G$4957,$A7)/$B7,"") -> 0.1187222 | Q7: =IFERROR(SUMIFS(Plans!$Y$2:$Y$4957,Plans!$A$2:$A$4957,Fixability!$C$3,Plans!$G$2:$G$4957,$A7)/$B7,"") -> 0.001470964 | R7: =IFERROR(SUMIFS(Plans!$Z$2:$Z$4957,Plans!$A$2:$A$4957,Fixability!$C$3,Plans!$G$2:$G$4957,$A7)/$B7,"") -> 0.35300707
A8: POS | B8: =SUM(C8:G8) -> 3829745 | C8: =SUMIFS(Plans!$AA$2:$AA$4957,Plans!$A$2:$A$4957,Fixability!$C$3,Plans!$G$2:$G$4957,$A8) -> 804333 | D8: =SUMIFS(Plans!$AB$2:$AB$4957,Plans!$A$2:$A$4957,Fixability!$C$3,Plans!$G$2:$G$4957,$A8) -> 52755 | E8: =SUMIFS(Plans!$AC$2:$AC$4957,Plans!$A$2:$A$4957,Fixability!$C$3,Plans!$G$2:$G$4957,$A8) -> 481623 | F8: =SUMIFS(Plans!$AD$2:$AD$4957,Plans!$A$2:$A$4957,Fixability!$C$3,Plans!$G$2:$G$4957,$A8) -> 569626 | G8: =SUMIFS(Plans!$AE$2:$AE$4957,Plans!$A$2:$A$4957,Fixability!$C$3,Plans!$G$2:$G$4957,$A8) -> 1921408 | H8: =IFERROR((C8+D8)/B8,"") -> 0.22379767 | I8: =IFERROR(SUMIFS(Plans!$Q$2:$Q$4957,Plans!$A$2:$A$4957,Fixability!$C$3,Plans!$G$2:$G$4957,$A8)/$B8,"") -> 0.2100226 | J8: =IFERROR(SUMIFS(Plans!$R$2:$R$4957,Plans!$A$2:$A$4957,Fixability!$C$3,Plans!$G$2:$G$4957,$A8)/$B8,"") -> 0.012349647 | K8: =IFERROR(SUMIFS(Plans!$S$2:$S$4957,Plans!$A$2:$A$4957,Fixability!$C$3,Plans!$G$2:$G$4957,$A8)/$B8,"") -> 0.0014254213 | L8: =IFERROR(SUMIFS(Plans!$T$2:$T$4957,Plans!$A$2:$A$4957,Fixability!$C$3,Plans!$G$2:$G$4957,$A8)/$B8,"") -> 0.032404507 | M8: =IFERROR(SUMIFS(Plans!$U$2:$U$4957,Plans!$A$2:$A$4957,Fixability!$C$3,Plans!$G$2:$G$4957,$A8)/$B8,"") -> 0.080957609 | N8: =IFERROR(SUMIFS(Plans!$V$2:$V$4957,Plans!$A$2:$A$4957,Fixability!$C$3,Plans!$G$2:$G$4957,$A8)/$B8,"") -> 0.012396387 | O8: =IFERROR(SUMIFS(Plans!$W$2:$W$4957,Plans!$A$2:$A$4957,Fixability!$C$3,Plans!$G$2:$G$4957,$A8)/$B8,"") -> 0.040373445 | P8: =IFERROR(SUMIFS(Plans!$X$2:$X$4957,Plans!$A$2:$A$4957,Fixability!$C$3,Plans!$G$2:$G$4957,$A8)/$B8,"") -> 0.10766696 | Q8: =IFERROR(SUMIFS(Plans!$Y$2:$Y$4957,Plans!$A$2:$A$4957,Fixability!$C$3,Plans!$G$2:$G$4957,$A8)/$B8,"") -> 0.00069691324 | R8: =IFERROR(SUMIFS(Plans!$Z$2:$Z$4957,Plans!$A$2:$A$4957,Fixability!$C$3,Plans!$G$2:$G$4957,$A8)/$B8,"") -> 0.50170651
A9: Indemnity | B9: =SUM(C9:G9) -> 0 | C9: =SUMIFS(Plans!$AA$2:$AA$4957,Plans!$A$2:$A$4957,Fixability!$C$3,Plans!$G$2:$G$4957,$A9) -> 0 | D9: =SUMIFS(Plans!$AB$2:$AB$4957,Plans!$A$2:$A$4957,Fixability!$C$3,Plans!$G$2:$G$4957,$A9) -> 0 | E9: =SUMIFS(Plans!$AC$2:$AC$4957,Plans!$A$2:$A$4957,Fixability!$C$3,Plans!$G$2:$G$4957,$A9) -> 0 | F9: =SUMIFS(Plans!$AD$2:$AD$4957,Plans!$A$2:$A$4957,Fixability!$C$3,Plans!$G$2:$G$4957,$A9) -> 0 | G9: =SUMIFS(Plans!$AE$2:$AE$4957,Plans!$A$2:$A$4957,Fixability!$C$3,Plans!$G$2:$G$4957,$A9) -> 0 | H9: =IFERROR((C9+D9)/B9,"") | I9: =IFERROR(SUMIFS(Plans!$Q$2:$Q$4957,Plans!$A$2:$A$4957,Fixability!$C$3,Plans!$G$2:$G$4957,$A9)/$B9,"") | J9: =IFERROR(SUMIFS(Plans!$R$2:$R$4957,Plans!$A$2:$A$4957,Fixability!$C$3,Plans!$G$2:$G$4957,$A9)/$B9,"") | K9: =IFERROR(SUMIFS(Plans!$S$2:$S$4957,Plans!$A$2:$A$4957,Fixability!$C$3,Plans!$G$2:$G$4957,$A9)/$B9,"") | L9: =IFERROR(SUMIFS(Plans!$T$2:$T$4957,Plans!$A$2:$A$4957,Fixability!$C$3,Plans!$G$2:$G$4957,$A9)/$B9,"") | M9: =IFERROR(SUMIFS(Plans!$U$2:$U$4957,Plans!$A$2:$A$4957,Fixability!$C$3,Plans!$G$2:$G$4957,$A9)/$B9,"") | N9: =IFERROR(SUMIFS(Plans!$V$2:$V$4957,Plans!$A$2:$A$4957,Fixability!$C$3,Plans!$G$2:$G$4957,$A9)/$B9,"") | O9: =IFERROR(SUMIFS(Plans!$W$2:$W$4957,Plans!$A$2:$A$4957,Fixability!$C$3,Plans!$G$2:$G$4957,$A9)/$B9,"") | P9: =IFERROR(SUMIFS(Plans!$X$2:$X$4957,Plans!$A$2:$A$4957,Fixability!$C$3,Plans!$G$2:$G$4957,$A9)/$B9,"") | Q9: =IFERROR(SUMIFS(Plans!$Y$2:$Y$4957,Plans!$A$2:$A$4957,Fixability!$C$3,Plans!$G$2:$G$4957,$A9)/$B9,"") | R9: =IFERROR(SUMIFS(Plans!$Z$2:$Z$4957,Plans!$A$2:$A$4957,Fixability!$C$3,Plans!$G$2:$G$4957,$A9)/$B9,"")
A10: All | B10: =SUM(B5:B9) -> 87173324 | C10: =SUM(C5:C9) -> 19612209 | D10: =SUM(D5:D9) -> 3968921 | E10: =SUM(E5:E9) -> 21601333 | F10: =SUM(F5:F9) -> 13877230 | G10: =SUM(G5:G9) -> 28113631 | H10: =IFERROR((C10+D10)/B10,"") -> 0.27050856 | I10: =IFERROR(SUMIFS(Plans!$Q$2:$Q$4957,Plans!$A$2:$A$4957,Fixability!$C$3)/$B10,"") -> 0.22497948 | J10: =IFERROR(SUMIFS(Plans!$R$2:$R$4957,Plans!$A$2:$A$4957,Fixability!$C$3)/$B10,"") -> 0.041234254 | K10: =IFERROR(SUMIFS(Plans!$S$2:$S$4957,Plans!$A$2:$A$4957,Fixability!$C$3)/$B10,"") -> 0.004294823 | L10: =IFERROR(SUMIFS(Plans!$T$2:$T$4957,Plans!$A$2:$A$4957,Fixability!$C$3)/$B10,"") -> 0.083794556 | M10: =IFERROR(SUMIFS(Plans!$U$2:$U$4957,Plans!$A$2:$A$4957,Fixability!$C$3)/$B10,"") -> 0.065720885 | N10: =IFERROR(SUMIFS(Plans!$V$2:$V$4957,Plans!$A$2:$A$4957,Fixability!$C$3)/$B10,"") -> 0.098282073 | O10: =IFERROR(SUMIFS(Plans!$W$2:$W$4957,Plans!$A$2:$A$4957,Fixability!$C$3)/$B10,"") -> 0.041830538 | P10: =IFERROR(SUMIFS(Plans!$X$2:$X$4957,Plans!$A$2:$A$4957,Fixability!$C$3)/$B10,"") -> 0.11619508 | Q10: =IFERROR(SUMIFS(Plans!$Y$2:$Y$4957,Plans!$A$2:$A$4957,Fixability!$C$3)/$B10,"") -> 0.0011656318 | R10: =IFERROR(SUMIFS(Plans!$Z$2:$Z$4957,Plans!$A$2:$A$4957,Fixability!$C$3)/$B10,"") -> 0.32250268

Sheet By Metal Level
A1: Denial reasons by Metal Level — market: | D1: =Fixability!$C$3 -> Individual Medical
A2: Counts by fixability tier, then each reason as a share of that row's classified denials. Change the market on the Fixability tab.
A4: Metal Level | B4: Denials With Reason | C4: Tier 1 High | D4: Tier 2 Medium-High | E4: Tier 3 Medium | F4: Tier 4 Low | G4: Tier 5 Unknown | H4: % Fixable (High + Med-High) | I4: % Administrative | J4: % Not medically necessary (medical) | K4: % Not medically necessary (behavioral health) | L4: % Referral required | M4: % Member not covered | N4: % Out-of-network | O4: % Benefit limit reached | P4: % Service excluded | Q4: % Experimental / cosmetic | R4: % Other / unspecified
A5: Bronze | B5: =SUM(C5:G5) -> 21903982 | C5: =SUMIFS(Plans!$AA$2:$AA$4957,Plans!$A$2:$A$4957,Fixability!$C$3,Plans!$H$2:$H$4957,$A5) -> 5505622 | D5: =SUMIFS(Plans!$AB$2:$AB$4957,Plans!$A$2:$A$4957,Fixability!$C$3,Plans!$H$2:$H$4957,$A5) -> 680817 | E5: =SUMIFS(Plans!$AC$2:$AC$4957,Plans!$A$2:$A$4957,Fixability!$C$3,Plans!$H$2:$H$4957,$A5) -> 5818565 | F5: =SUMIFS(Plans!$AD$2:$AD$4957,Plans!$A$2:$A$4957,Fixability!$C$3,Plans!$H$2:$H$4957,$A5) -> 3042801 | G5: =SUMIFS(Plans!$AE$2:$AE$4957,Plans!$A$2:$A$4957,Fixability!$C$3,Plans!$H$2:$H$4957,$A5) -> 6856177 | H5: =IFERROR((C5+D5)/B5,"") -> 0.28243445 | I5: =IFERROR(SUMIFS(Plans!$Q$2:$Q$4957,Plans!$A$2:$A$4957,Fixability!$C$3,Plans!$H$2:$H$4957,$A5)/$B5,"") -> 0.25135256 | J5: =IFERROR(SUMIFS(Plans!$R$2:$R$4957,Plans!$A$2:$A$4957,Fixability!$C$3,Plans!$H$2:$H$4957,$A5)/$B5,"") -> 0.027512167 | K5: =IFERROR(SUMIFS(Plans!$S$2:$S$4957,Plans!$A$2:$A$4957,Fixability!$C$3,Plans!$H$2:$H$4957,$A5)/$B5,"") -> 0.0035697162 | L5: =IFERROR(SUMIFS(Plans!$T$2:$T$4957,Plans!$A$2:$A$4957,Fixability!$C$3,Plans!$H$2:$H$4957,$A5)/$B5,"") -> 0.06708141 | M5: =IFERROR(SUMIFS(Plans!$U$2:$U$4957,Plans!$A$2:$A$4957,Fixability!$C$3,Plans!$H$2:$H$4957,$A5)/$B5,"") -> 0.070291237 | N5: =IFERROR(SUMIFS(Plans!$V$2:$V$4957,Plans!$A$2:$A$4957,Fixability!$C$3,Plans!$H$2:$H$4957,$A5)/$B5,"") -> 0.12826695 | O5: =IFERROR(SUMIFS(Plans!$W$2:$W$4957,Plans!$A$2:$A$4957,Fixability!$C$3,Plans!$H$2:$H$4957,$A5)/$B5,"") -> 0.033215787 | P5: =IFERROR(SUMIFS(Plans!$X$2:$X$4957,Plans!$A$2:$A$4957,Fixability!$C$3,Plans!$H$2:$H$4957,$A5)/$B5,"") -> 0.10482478 | Q5: =IFERROR(SUMIFS(Plans!$Y$2:$Y$4957,Plans!$A$2:$A$4957,Fixability!$C$3,Plans!$H$2:$H$4957,$A5)/$B5,"") -> 0.00087486376 | R5: =IFERROR(SUMIFS(Plans!$Z$2:$Z$4957,Plans!$A$2:$A$4957,Fixability!$C$3,Plans!$H$2:$H$4957,$A5)/$B5,"") -> 0.31301053
A6: Silver | B6: =SUM(C6:G6) -> 52457939 | C6: =SUMIFS(Plans!$AA$2:$AA$4957,Plans!$A$2:$A$4957,Fixability!$C$3,Plans!$H$2:$H$4957,$A6) -> 12097390 | D6: =SUMIFS(Plans!$AB$2:$AB$4957,Plans!$A$2:$A$4957,Fixability!$C$3,Plans!$H$2:$H$4957,$A6) -> 2743383 | E6: =SUMIFS(Plans!$AC$2:$AC$4957,Plans!$A$2:$A$4957,Fixability!$C$3,Plans!$H$2:$H$4957,$A6) -> 12740161 | F6: =SUMIFS(Plans!$AD$2:$AD$4957,Plans!$A$2:$A$4957,Fixability!$C$3,Plans!$H$2:$H$4957,$A6) -> 8582811 | G6: =SUMIFS(Plans!$AE$2:$AE$4957,Plans!$A$2:$A$4957,Fixability!$C$3,Plans!$H$2:$H$4957,$A6) -> 16294194 | H6: =IFERROR((C6+D6)/B6,"") -> 0.28290805 | I6: =IFERROR(SUMIFS(Plans!$Q$2:$Q$4957,Plans!$A$2:$A$4957,Fixability!$C$3,Plans!$H$2:$H$4957,$A6)/$B6,"") -> 0.23061123 | J6: =IFERROR(SUMIFS(Plans!$R$2:$R$4957,Plans!$A$2:$A$4957,Fixability!$C$3,Plans!$H$2:$H$4957,$A6)/$B6,"") -> 0.047540888 | K6: =IFERROR(SUMIFS(Plans!$S$2:$S$4957,Plans!$A$2:$A$4957,Fixability!$C$3,Plans!$H$2:$H$4957,$A6)/$B6,"") -> 0.0047559246 | L6: =IFERROR(SUMIFS(Plans!$T$2:$T$4957,Plans!$A$2:$A$4957,Fixability!$C$3,Plans!$H$2:$H$4957,$A6)/$B6,"") -> 0.088672756 | M6: =IFERROR(SUMIFS(Plans!$U$2:$U$4957,Plans!$A$2:$A$4957,Fixability!$C$3,Plans!$H$2:$H$4957,$A6)/$B6,"") -> 0.064259349 | N6: =IFERROR(SUMIFS(Plans!$V$2:$V$4957,Plans!$A$2:$A$4957,Fixability!$C$3,Plans!$H$2:$H$4957,$A6)/$B6,"") -> 0.089932203 | O6: =IFERROR(SUMIFS(Plans!$W$2:$W$4957,Plans!$A$2:$A$4957,Fixability!$C$3,Plans!$H$2:$H$4957,$A6)/$B6,"") -> 0.047790231 | P6: =IFERROR(SUMIFS(Plans!$X$2:$X$4957,Plans!$A$2:$A$4957,Fixability!$C$3,Plans!$H$2:$H$4957,$A6)/$B6,"") -> 0.11457362 | Q6: =IFERROR(SUMIFS(Plans!$Y$2:$Y$4957,Plans!$A$2:$A$4957,Fixability!$C$3,Plans!$H$2:$H$4957,$A6)/$B6,"") -> 0.0012493438 | R6: =IFERROR(SUMIFS(Plans!$Z$2:$Z$4957,Plans!$A$2:$A$4957,Fixability!$C$3,Plans!$H$2:$H$4957,$A6)/$B6,"") -> 0.31061445
A7: Gold | B7: =SUM(C7:G7) -> 12352677 | C7: =SUMIFS(Plans!$AA$2:$AA$4957,Plans!$A$2:$A$4957,Fixability!$C$3,Plans!$H$2:$H$4957,$A7) -> 1874771 | D7: =SUMIFS(Plans!$AB$2:$AB$4957,Plans!$A$2:$A$4957,Fixability!$C$3,Plans!$H$2:$H$4957,$A7) -> 542489 | E7: =SUMIFS(Plans!$AC$2:$AC$4957,Plans!$A$2:$A$4957,Fixability!$C$3,Plans!$H$2:$H$4957,$A7) -> 2994015 | F7: =SUMIFS(Plans!$AD$2:$AD$4957,Plans!$A$2:$A$4957,Fixability!$C$3,Plans!$H$2:$H$4957,$A7) -> 2218952 | G7: =SUMIFS(Plans!$AE$2:$AE$4957,Plans!$A$2:$A$4957,Fixability!$C$3,Plans!$H$2:$H$4957,$A7) -> 4722450 | H7: =IFERROR((C7+D7)/B7,"") -> 0.19568714 | I7: =IFERROR(SUMIFS(Plans!$Q$2:$Q$4957,Plans!$A$2:$A$4957,Fixability!$C$3,Plans!$H$2:$H$4957,$A7)/$B7,"") -> 0.15177042 | J7: =IFERROR(SUMIFS(Plans!$R$2:$R$4957,Plans!$A$2:$A$4957,Fixability!$C$3,Plans!$H$2:$H$4957,$A7)/$B7,"") -> 0.040173964 | K7: =IFERROR(SUMIFS(Plans!$S$2:$S$4957,Plans!$A$2:$A$4957,Fixability!$C$3,Plans!$H$2:$H$4957,$A7)/$B7,"") -> 0.0037427515 | L7: =IFERROR(SUMIFS(Plans!$T$2:$T$4957,Plans!$A$2:$A$4957,Fixability!$C$3,Plans!$H$2:$H$4957,$A7)/$B7,"") -> 0.095204546 | M7: =IFERROR(SUMIFS(Plans!$U$2:$U$4957,Plans!$A$2:$A$4957,Fixability!$C$3,Plans!$H$2:$H$4957,$A7)/$B7,"") -> 0.064867963 | N7: =IFERROR(SUMIFS(Plans!$V$2:$V$4957,Plans!$A$2:$A$4957,Fixability!$C$3,Plans!$H$2:$H$4957,$A7)/$B7,"") -> 0.082305317 | O7: =IFERROR(SUMIFS(Plans!$W$2:$W$4957,Plans!$A$2:$A$4957,Fixability!$C$3,Plans!$H$2:$H$4957,$A7)/$B7,"") -> 0.032256085 | P7: =IFERROR(SUMIFS(Plans!$X$2:$X$4957,Plans!$A$2:$A$4957,Fixability!$C$3,Plans!$H$2:$H$4957,$A7)/$B7,"") -> 0.14604292 | Q7: =IFERROR(SUMIFS(Plans!$Y$2:$Y$4957,Plans!$A$2:$A$4957,Fixability!$C$3,Plans!$H$2:$H$4957,$A7)/$B7,"") -> 0.0013342857 | R7: =IFERROR(SUMIFS(Plans!$Z$2:$Z$4957,Plans!$A$2:$A$4957,Fixability!$C$3,Plans!$H$2:$H$4957,$A7)/$B7,"") -> 0.38230175
A8: Platinum | B8: =SUM(C8:G8) -> 398557 | C8: =SUMIFS(Plans!$AA$2:$AA$4957,Plans!$A$2:$A$4957,Fixability!$C$3,Plans!$H$2:$H$4957,$A8) -> 125402 | D8: =SUMIFS(Plans!$AB$2:$AB$4957,Plans!$A$2:$A$4957,Fixability!$C$3,Plans!$H$2:$H$4957,$A8) -> 1116 | E8: =SUMIFS(Plans!$AC$2:$AC$4957,Plans!$A$2:$A$4957,Fixability!$C$3,Plans!$H$2:$H$4957,$A8) -> 21542 | F8: =SUMIFS(Plans!$AD$2:$AD$4957,Plans!$A$2:$A$4957,Fixability!$C$3,Plans!$H$2:$H$4957,$A8) -> 21600 | G8: =SUMIFS(Plans!$AE$2:$AE$4957,Plans!$A$2:$A$4957,Fixability!$C$3,Plans!$H$2:$H$4957,$A8) -> 228897 | H8: =IFERROR((C8+D8)/B8,"") -> 0.31744017 | I8: =IFERROR(SUMIFS(Plans!$Q$2:$Q$4957,Plans!$A$2:$A$4957,Fixability!$C$3,Plans!$H$2:$H$4957,$A8)/$B8,"") -> 0.31464006 | J8: =IFERROR(SUMIFS(Plans!$R$2:$R$4957,Plans!$A$2:$A$4957,Fixability!$C$3,Plans!$H$2:$H$4957,$A8)/$B8,"") -> 0.0020072411 | K8: =IFERROR(SUMIFS(Plans!$S$2:$S$4957,Plans!$A$2:$A$4957,Fixability!$C$3,Plans!$H$2:$H$4957,$A8)/$B8,"") -> 0.00079286024 | L8: =IFERROR(SUMIFS(Plans!$T$2:$T$4957,Plans!$A$2:$A$4957,Fixability!$C$3,Plans!$H$2:$H$4957,$A8)/$B8,"") -> 0.01076634 | M8: =IFERROR(SUMIFS(Plans!$U$2:$U$4957,Plans!$A$2:$A$4957,Fixability!$C$3,Plans!$H$2:$H$4957,$A8)/$B8,"") -> 0.0036080159 | N8: =IFERROR(SUMIFS(Plans!$V$2:$V$4957,Plans!$A$2:$A$4957,Fixability!$C$3,Plans!$H$2:$H$4957,$A8)/$B8,"") -> 0.03967563 | O8: =IFERROR(SUMIFS(Plans!$W$2:$W$4957,Plans!$A$2:$A$4957,Fixability!$C$3,Plans!$H$2:$H$4957,$A8)/$B8,"") -> 0.026074062 | P8: =IFERROR(SUMIFS(Plans!$X$2:$X$4957,Plans!$A$2:$A$4957,Fixability!$C$3,Plans!$H$2:$H$4957,$A8)/$B8,"") -> 0.027188081 | Q8: =IFERROR(SUMIFS(Plans!$Y$2:$Y$4957,Plans!$A$2:$A$4957,Fixability!$C$3,Plans!$H$2:$H$4957,$A8)/$B8,"") -> 0.00093336712 | R8: =IFERROR(SUMIFS(Plans!$Z$2:$Z$4957,Plans!$A$2:$A$4957,Fixability!$C$3,Plans!$H$2:$H$4957,$A8)/$B8,"") -> 0.57431434
A9: Catastrophic | B9: =SUM(C9:G9) -> 60169 | C9: =SUMIFS(Plans!$AA$2:$AA$4957,Plans!$A$2:$A$4957,Fixability!$C$3,Plans!$H$2:$H$4957,$A9) -> 9024 | D9: =SUMIFS(Plans!$AB$2:$AB$4957,Plans!$A$2:$A$4957,Fixability!$C$3,Plans!$H$2:$H$4957,$A9) -> 1116 | E9: =SUMIFS(Plans!$AC$2:$AC$4957,Plans!$A$2:$A$4957,Fixability!$C$3,Plans!$H$2:$H$4957,$A9) -> 27050 | F9: =SUMIFS(Plans!$AD$2:$AD$4957,Plans!$A$2:$A$4957,Fixability!$C$3,Plans!$H$2:$H$4957,$A9) -> 11066 | G9: =SUMIFS(Plans!$AE$2:$AE$4957,Plans!$A$2:$A$4957,Fixability!$C$3,Plans!$H$2:$H$4957,$A9) -> 11913 | H9: =IFERROR((C9+D9)/B9,"") -> 0.16852532 | I9: =IFERROR(SUMIFS(Plans!$Q$2:$Q$4957,Plans!$A$2:$A$4957,Fixability!$C$3,Plans!$H$2:$H$4957,$A9)/$B9,"") -> 0.14997756 | J9: =IFERROR(SUMIFS(Plans!$R$2:$R$4957,Plans!$A$2:$A$4957,Fixability!$C$3,Plans!$H$2:$H$4957,$A9)/$B9,"") -> 0.015755622 | K9: =IFERROR(SUMIFS(Plans!$S$2:$S$4957,Plans!$A$2:$A$4957,Fixability!$C$3,Plans!$H$2:$H$4957,$A9)/$B9,"") -> 0.0027921355 | L9: =IFERROR(SUMIFS(Plans!$T$2:$T$4957,Plans!$A$2:$A$4957,Fixability!$C$3,Plans!$H$2:$H$4957,$A9)/$B9,"") -> 0.056308066 | M9: =IFERROR(SUMIFS(Plans!$U$2:$U$4957,Plans!$A$2:$A$4957,Fixability!$C$3,Plans!$H$2:$H$4957,$A9)/$B9,"") -> 0.26269341 | N9: =IFERROR(SUMIFS(Plans!$V$2:$V$4957,Plans!$A$2:$A$4957,Fixability!$C$3,Plans!$H$2:$H$4957,$A9)/$B9,"") -> 0.13056557 | O9: =IFERROR(SUMIFS(Plans!$W$2:$W$4957,Plans!$A$2:$A$4957,Fixability!$C$3,Plans!$H$2:$H$4957,$A9)/$B9,"") -> 0.052036763 | P9: =IFERROR(SUMIFS(Plans!$X$2:$X$4957,Plans!$A$2:$A$4957,Fixability!$C$3,Plans!$H$2:$H$4957,$A9)/$B9,"") -> 0.13093121 | Q9: =IFERROR(SUMIFS(Plans!$Y$2:$Y$4957,Plans!$A$2:$A$4957,Fixability!$C$3,Plans!$H$2:$H$4957,$A9)/$B9,"") -> 0.00094733168 | R9: =IFERROR(SUMIFS(Plans!$Z$2:$Z$4957,Plans!$A$2:$A$4957,Fixability!$C$3,Plans!$H$2:$H$4957,$A9)/$B9,"") -> 0.19799232
A10: High | B10: =SUM(C10:G10) -> 0 | C10: =SUMIFS(Plans!$AA$2:$AA$4957,Plans!$A$2:$A$4957,Fixability!$C$3,Plans!$H$2:$H$4957,$A10) -> 0 | D10: =SUMIFS(Plans!$AB$2:$AB$4957,Plans!$A$2:$A$4957,Fixability!$C$3,Plans!$H$2:$H$4957,$A10) -> 0 | E10: =SUMIFS(Plans!$AC$2:$AC$4957,Plans!$A$2:$A$4957,Fixability!$C$3,Plans!$H$2:$H$4957,$A10) -> 0 | F10: =SUMIFS(Plans!$AD$2:$AD$4957,Plans!$A$2:$A$4957,Fixability!$C$3,Plans!$H$2:$H$4957,$A10) -> 0 | G10: =SUMIFS(Plans!$AE$2:$AE$4957,Plans!$A$2:$A$4957,Fixability!$C$3,Plans!$H$2:$H$4957,$A10) -> 0 | H10: =IFERROR((C10+D10)/B10,"") | I10: =IFERROR(SUMIFS(Plans!$Q$2:$Q$4957,Plans!$A$2:$A$4957,Fixability!$C$3,Plans!$H$2:$H$4957,$A10)/$B10,"") | J10: =IFERROR(SUMIFS(Plans!$R$2:$R$4957,Plans!$A$2:$A$4957,Fixability!$C$3,Plans!$H$2:$H$4957,$A10)/$B10,"") | K10: =IFERROR(SUMIFS(Plans!$S$2:$S$4957,Plans!$A$2:$A$4957,Fixability!$C$3,Plans!$H$2:$H$4957,$A10)/$B10,"") | L10: =IFERROR(SUMIFS(Plans!$T$2:$T$4957,Plans!$A$2:$A$4957,Fixability!$C$3,Plans!$H$2:$H$4957,$A10)/$B10,"") | M10: =IFERROR(SUMIFS(Plans!$U$2:$U$4957,Plans!$A$2:$A$4957,Fixability!$C$3,Plans!$H$2:$H$4957,$A10)/$B10,"") | N10: =IFERROR(SUMIFS(Plans!$V$2:$V$4957,Plans!$A$2:$A$4957,Fixability!$C$3,Plans!$H$2:$H$4957,$A10)/$B10,"") | O10: =IFERROR(SUMIFS(Plans!$W$2:$W$4957,Plans!$A$2:$A$4957,Fixability!$C$3,Plans!$H$2:$H$4957,$A10)/$B10,"") | P10: =IFERROR(SUMIFS(Plans!$X$2:$X$4957,Plans!$A$2:$A$4957,Fixability!$C$3,Plans!$H$2:$H$4957,$A10)/$B10,"") | Q10: =IFERROR(SUMIFS(Plans!$Y$2:$Y$4957,Plans!$A$2:$A$4957,Fixability!$C$3,Plans!$H$2:$H$4957,$A10)/$B10,"") | R10: =IFERROR(SUMIFS(Plans!$Z$2:$Z$4957,Plans!$A$2:$A$4957,Fixability!$C$3,Plans!$H$2:$H$4957,$A10)/$B10,"")
A11: Low | B11: =SUM(C11:G11) -> 0 | C11: =SUMIFS(Plans!$AA$2:$AA$4957,Plans!$A$2:$A$4957,Fixability!$C$3,Plans!$H$2:$H$4957,$A11) -> 0 | D11: =SUMIFS(Plans!$AB$2:$AB$4957,Plans!$A$2:$A$4957,Fixability!$C$3,Plans!$H$2:$H$4957,$A11) -> 0 | E11: =SUMIFS(Plans!$AC$2:$AC$4957,Plans!$A$2:$A$4957,Fixability!$C$3,Plans!$H$2:$H$4957,$A11) -> 0 | F11: =SUMIFS(Plans!$AD$2:$AD$4957,Plans!$A$2:$A$4957,Fixability!$C$3,Plans!$H$2:$H$4957,$A11) -> 0 | G11: =SUMIFS(Plans!$AE$2:$AE$4957,Plans!$A$2:$A$4957,Fixability!$C$3,Plans!$H$2:$H$4957,$A11) -> 0 | H11: =IFERROR((C11+D11)/B11,"") | I11: =IFERROR(SUMIFS(Plans!$Q$2:$Q$4957,Plans!$A$2:$A$4957,Fixability!$C$3,Plans!$H$2:$H$4957,$A11)/$B11,"") | J11: =IFERROR(SUMIFS(Plans!$R$2:$R$4957,Plans!$A$2:$A$4957,Fixability!$C$3,Plans!$H$2:$H$4957,$A11)/$B11,"") | K11: =IFERROR(SUMIFS(Plans!$S$2:$S$4957,Plans!$A$2:$A$4957,Fixability!$C$3,Plans!$H$2:$H$4957,$A11)/$B11,"") | L11: =IFERROR(SUMIFS(Plans!$T$2:$T$4957,Plans!$A$2:$A$4957,Fixability!$C$3,Plans!$H$2:$H$4957,$A11)/$B11,"") | M11: =IFERROR(SUMIFS(Plans!$U$2:$U$4957,Plans!$A$2:$A$4957,Fixability!$C$3,Plans!$H$2:$H$4957,$A11)/$B11,"") | N11: =IFERROR(SUMIFS(Plans!$V$2:$V$4957,Plans!$A$2:$A$4957,Fixability!$C$3,Plans!$H$2:$H$4957,$A11)/$B11,"") | O11: =IFERROR(SUMIFS(Plans!$W$2:$W$4957,Plans!$A$2:$A$4957,Fixability!$C$3,Plans!$H$2:$H$4957,$A11)/$B11,"") | P11: =IFERROR(SUMIFS(Plans!$X$2:$X$4957,Plans!$A$2:$A$4957,Fixability!$C$3,Plans!$H$2:$H$4957,$A11)/$B11,"") | Q11: =IFERROR(SUMIFS(Plans!$Y$2:$Y$4957,Plans!$A$2:$A$4957,Fixability!$C$3,Plans!$H$2:$H$4957,$A11)/$B11,"") | R11: =IFERROR(SUMIFS(Plans!$Z$2:$Z$4957,Plans!$A$2:$A$4957,Fixability!$C$3,Plans!$H$2:$H$4957,$A11)/$B11,"")
